Workbook

Sheet Welcome
A2: Welcome to Apex Girls Resources Info | H2: by @SrCuentaOficial
H3: Server 717. Migrate Now!
A4: Each level shows the resources needed to reach the next level.
M5: Update Notes
A6: Leave a comment, or send a screenshot if you'd like to help complete it. | M6: 23/01/2026 | N6: New calculator for total resource requirements by level range.
N7: Works for Artists, Assets, HQ, Collections, Car and Villa levels.
B8: Resource Type | D8: Complete Data | G8: Incomplete Data | M8: 22/01/2026 | N8: Added a new table detailing Promotion Cost (Assets Required) in the Assets tab.
B9: Car Parts (Pieces) | D9: Class A to SS-4stars | G9: Class SS-5stars to SSS-5stars | M9: 19/01/2026 | N9: Master Blueprint tables added to the Blueprints Tab (information still pending)
B10: Car Parts (Drawings) | D10: Class A to SS-4stars | G10: Class SS-5stars to SSS-5stars | M10: 19/01/2026 | N10: Carcore and Homemaking total amounts changed from levels 1–60 to 38–60.
B11: Car Core (Plugs and Coils) | D11: Tier D to A+ | G11: All Complete | N11: Applies to Tier 2 and above.
B12: HQ Glass | D12: Level 1 to 425 | G12: Levels 426 to 600 | M12: 29/12/2025 | N12: Total amounts added to Floors,Exhibits,Homeking,CarCore Tab
B13: HQ Floors (Wood and Steel) | D13: Floor1 to Floor3 | G13: Floor4 and Floor5
B14: Collection Gems | D14: Level 1 to 50 | G14: All Complete
B15: Museum Rooms (Sandstone and Tiles) | D15: Room 1 to 5 | G15: All Complete
B16: Villa Suite (Drones) | D16: Classic Villa, Elite Villa, Prestige Villa, Luxury Villa, Summit Villa, Iconic Villa and Urban Heights | G16: All Complete
B17: Villa Suite (Design Drafts) | D17: Classic Villa, Elite Villa, Prestige Villa, Luxury Villa, Summit Villa, Iconic Villa. | G17: Urban Heights
B18: Villa Homemaking (Coins and Keys) | D18: Tier 1 to 4 | G18: All Complete
B19: Assets Coins (Basic, Abroad, and Auction) | D19: Level 1 to 60 | G19: All Complete
B20: Artist (EXP and Promotion Cards) | D20: Level 1 to 140 | G20: All Complete
B21: Blueprints | D21: Tier 1 to 21 | G21: All Complete
B22: Master Blueprints | D22: Incomplete | G22: Incomplete
B23: Building Cards | D23: Level 1 to 15 | G23: All Complete
B24: Street Business Gold | D24: Level 1 to 15 | G24: All Complete

Sheet Calculator
A1: LEVEL PROGRESSION COST CALCULATOR | I1: @SrCuentaOficial | J1: Server 717. Migrate Now!
A2: ONLY COMPLETE LEVELS ARE AVAILABLE
A3: HQ GLASS | F3: HQ FLOORS
A4: *Available up to level 426 | F4: Floor | G4: 3 | H4: *Use Only for Floors 1, 2 and 3
A5: From Level | B5: 273 | C5: To Level | D5: 370 | F5: From Level | G5: 1 | H5: To Level | I5: 60
A6: You need | B6: =VLOOKUP(D5-1,Tables!$A$2:$C$603,3,0)-VLOOKUP(B5-1,Tables!$A$2:$C$603,3,0) -> 301670 | C6: Glass | F6: You need | G6: =VLOOKUP(I5-1,Tables!$BH$2:$BR$63,G4*2,0)-VLOOKUP(G5-1,Tables!$BH$2:$BR$63,G4*2,0) -> 30000 | H6: =IF($G$4>3,"HQ Wood","Wood") -> Wood | I6: =IF($G$4>3,"equals","") | J6: =IF($G$4>3,G6*125,"") | K6: =IF($G$4>3,"Wood","")
G7: =VLOOKUP(I5-1,Tables!$BH$2:$BR$63,G4*2+1,0)-VLOOKUP(G5-1,Tables!$BH$2:$BR$63,G4*2+1,0) -> 3000 | H7: =IF($G$4>3,"HQ Steel","Steel") -> Steel | I7: =IF($G$4>3,"equals","") | J7: =IF($G$4>3,G7*125,"") | K7: =IF($G$4>3,"Steel","")
A8: COLLECTION GEMS | F8: MUSEUM EXHIBITS
F9: Exhibit
A10: From Level | B10: 31 | C10: To Level | D10: 35 | F10: From Level | G10: 1 | H10: To Level | I10: 2
A11: You need | B11: =VLOOKUP(D10-1,Tables!$D$2:$F$53,3,0)-VLOOKUP(B10-1,Tables!$D$2:$F$53,3,0) -> 18251 | C11: Gems | F11: You need | G11: =VLOOKUP(I10-1,Tables!$BS$2:$CC$63,G10*2,0)-VLOOKUP(#REF!-1,Tables!$BS$2:$CC$63,G10*2,0) -> #REF! | H11: =IF($G$10>3,"HQ Sandstone","Sandstone") -> Sandstone | I11: =IF($G$10>3,"equals","") | J11: =IF($G$10>3,G11*125,"") | K11: =IF($G$10>3,"Sandstone","")
G12: =VLOOKUP(I10-1,Tables!$BS$2:$CC$63,G10*2+1,0)-VLOOKUP(#REF!-1,Tables!$BS$2:$CC$63,G10*2+1,0) -> #REF! | H12: =IF($G$10>3,"HQ Tiles","Tiles") -> Tiles | I12: =IF($G$10>3,"equals","") | J12: =IF($G$10>3,G12*125,"") | K12: =IF($G$10>3,"Tiles","")
A13: CAR PARTS | F13: CAR CORE
A14: Rank + #Stars | C14: *Available until SSS1 | F14: Rank | G14: A
A15: From Level | B15: SS3 | C15: To Level | D15: SS5 | F15: From Level | G15: 38 | H15: To Level | I15: 60
A16: You need | B16: =VLOOKUP(D15,Tables!$G$2:$K$36,3,0)-VLOOKUP(B15,Tables!$G$2:$K$36,3,0) -> 208000 | C16: Parts | F16: You need | G16: =VLOOKUP(I15-1,Tables!$CD$2:$CN$63,VLOOKUP($G$14,Tables!$Q$2:$R$7,2,0)*2,0)-VLOOKUP(G15-1,Tables!$CD$2:$CN$63,VLOOKUP($G$14,Tables!$Q$2:$R$7,2,0)*2,0) -> 1600 | H16: =IF(OR($G$14="A",$G$14="A+"),"Enhanced Plugs","Plugs") -> Enhanced Plugs | I16: =IF(OR($G$14="A",$G$14="A+"),"equals","") -> equals | J16: =IF(OR($G$14="A",$G$14="A+"),G16*125,"") -> 200000 | K16: =IF(OR($G$14="A",$G$14="A+"),"Plugs","") -> Plugs
B17: =VLOOKUP(D15,Tables!$G$2:$K$36,5,0)-VLOOKUP(B15,Tables!$G$2:$K$36,5,0) -> 30000 | C17: Advance Drawings | G17: =VLOOKUP(I15-1,Tables!$CD$2:$CN$63,VLOOKUP($G$14,Tables!$Q$2:$R$7,2,0)*2+1,0)-VLOOKUP(G15-1,Tables!$CD$2:$CN$63,VLOOKUP($G$14,Tables!$Q$2:$R$7,2,0)*2+1,0) -> 181 | H17: =IF(OR($G$14="A",$G$14="A+"),"Enhanced Coils","Coils") -> Enhanced Coils | I17: =IF(OR($G$14="A",$G$14="A+"),"equals","") -> equals | J17: =IF(OR($G$14="A",$G$14="A+"),G17*125,"") -> 22625 | K17: =IF(OR($G$14="A",$G$14="A+"),"Coils","") -> Coils
A18: VILLA SUITE | F18: VILLA HOMEMAKING
A19: Villa + #Gold hammers | C19: *Until Urban Heights-0 | F19: Tier | G19: 5
A20: From Level | B20: Summit Villa-1 | F20: From Level | G20: 32 | H20: To Level | I20: 45
A21: To Level | B21: Summit Villa-3
A22: You need | B22: =VLOOKUP(B21,Tables!$L$2:$P$41,3,0)-VLOOKUP(B20,Tables!$L$2:$P$41,3,0) -> 120000 | C22: Drones | F22: You need | G22: =VLOOKUP(I20-1,Tables!$CO$2:$CY$63,$G$19*2,0)-VLOOKUP(G20-1,Tables!$CO$2:$CY$63,$G$19*2,0) -> 2115 | H22: =IF($G$19>3,"HQ Coins","Coins") -> HQ Coins | I22: =IF($G$19>3,"equals","") -> equals | J22: =IF($G$19>3,G22*125,"") -> 264375 | K22: =IF($G$19>3,"Coins","") -> Coins
B23: =VLOOKUP(B21,Tables!$L$2:$P$41,5,0)-VLOOKUP(B20,Tables!$L$2:$P$41,5,0) -> 3000 | C23: Design Drafts | G23: =VLOOKUP(I20-1,Tables!$CO$2:$CY$63,$G$19*2+1,0)-VLOOKUP(G20-1,Tables!$CO$2:$CY$63,$G$19*2+1,0) -> 260 | H23: =IF($G$19>3,"HQ Keys","Keys") -> HQ Keys | I23: =IF($G$19>3,"equals","") -> equals | J23: =IF($G$19>3,G23*125,"") -> 32500 | K23: =IF($G$19>3,"Keys","") -> Keys
A25: ARTISTS | F25: ASSETS
F26: Type | G26: Jewelry | H26: Source | I26: Standard
A27: From Level | B27: 1 | C27: To Level | D27: 140 | F27: From Level | G27: 32 | H27: To Level | I27: 60
A28: You need | B28: =VLOOKUP($D$27-1,Tables!$CZ$2:$DD$143,3,0)-VLOOKUP($B$27-1,Tables!$CZ$2:$DD$143,3,0) -> 341963600 | C28: EXP Cards | F28: You need | G28: =VLOOKUP($I$27-1,Tables!$DS$2:$EB$62,(VLOOKUP($I$26,Tables!$DF$2:$DG$5,2,0)-1)*3+1+VLOOKUP($G$26,Tables!$DE$2:$DG$5,3,0),0)-VLOOKUP($G$27-1,Tables!$DS$2:$EB$62,(VLOOKUP($I$26,Tables!$DF$2:$DG$5,2,0)-1)*3+1+VLOOKUP($G$26,Tables!$DE$2:$DG$5,3,0),0) -> 2835000 | H28: Asset Coins
B29: =VLOOKUP($D$27-1,Tables!$CZ$2:$DD$143,5,0)-VLOOKUP($B$27-1,Tables!$CZ$2:$DD$143,5,0) -> 15900 | C29: Promotion Cards | G29: =VLOOKUP(I27-1,Tables!$EC$2:$EE$63,3,0)-VLOOKUP(G27-1,Tables!$EC$2:$EE$63,3,0) -> 9 | H29: Extra Assets for Promotion

Sheet Glass
A1: HQ GLASS
A2: Level | B2: Glass | C2: Level | D2: Glass | E2: Level | F2: Glass | G2: Level | H2: Glass | I2: Level | J2: Glass | K2: Level | L2: Glass | M2: Level | N2: Glass | O2: Level | P2: Glass | Q2: Level | R2: Glass | S2: Level | T2: Glass | U2: Level | V2: Glass | W2: Level | X2: Glass
A3: 1 | B3: 5 | C3: 51 | D3: 410 | E3: 101 | F3: 910 | G3: 151 | H3: 1410 | I3: 201 | J3: 1910 | K3: 251 | L3: 2410 | M3: 301 | N3: 2910 | O3: 351 | P3: 3410 | Q3: 401 | R3: 3850 | S3: 451 | U3: 501 | W3: 551
A4: 2 | B4: 10 | C4: 52 | D4: 420 | E4: 102 | F4: 920 | G4: 152 | H4: 1420 | I4: 202 | J4: 1920 | K4: 252 | L4: 2420 | M4: 302 | N4: 2920 | O4: 352 | P4: 3420 | Q4: 402 | R4: 3900 | S4: 452 | U4: 502 | W4: 552
A5: 3 | B5: 15 | C5: 53 | D5: 430 | E5: 103 | F5: 930 | G5: 153 | H5: 1430 | I5: 203 | J5: 1930 | K5: 253 | L5: 2430 | M5: 303 | N5: 2930 | O5: 353 | P5: 3430 | Q5: 403 | R5: 3950 | S5: 453 | U5: 503 | W5: 553
A6: 4 | B6: 20 | C6: 54 | D6: 440 | E6: 104 | F6: 940 | G6: 154 | H6: 1440 | I6: 204 | J6: 1940 | K6: 254 | L6: 2440 | M6: 304 | N6: 2940 | O6: 354 | P6: 3440 | Q6: 404 | R6: 4000 | S6: 454 | U6: 504 | W6: 554
A7: 5 | B7: 25 | C7: 55 | D7: 450 | E7: 105 | F7: 950 | G7: 155 | H7: 1450 | I7: 205 | J7: 1950 | K7: 255 | L7: 2450 | M7: 305 | N7: 2950 | O7: 355 | P7: 3450 | Q7: 405 | R7: 4200 | S7: 455 | T7: 9300 | U7: 505 | W7: 555
A8: 6 | B8: 30 | C8: 56 | D8: 460 | E8: 106 | F8: 960 | G8: 156 | H8: 1460 | I8: 206 | J8: 1960 | K8: 256 | L8: 2460 | M8: 306 | N8: 2960 | O8: 356 | P8: 3460 | Q8: 406 | R8: 4250 | S8: 456 | T8: 9450 | U8: 506 | W8: 556
A9: 7 | B9: 35 | C9: 57 | D9: 470 | E9: 107 | F9: 970 | G9: 157 | H9: 1470 | I9: 207 | J9: 1970 | K9: 257 | L9: 2470 | M9: 307 | N9: 2970 | O9: 357 | P9: 3470 | Q9: 407 | R9: 4300 | S9: 457 | T9: 9600 | U9: 507 | W9: 557
A10: 8 | B10: 40 | C10: 58 | D10: 480 | E10: 108 | F10: 980 | G10: 158 | H10: 1480 | I10: 208 | J10: 1980 | K10: 258 | L10: 2480 | M10: 308 | N10: 2980 | O10: 358 | P10: 3480 | Q10: 408 | R10: 4350 | S10: 458 | T10: 9750 | U10: 508 | W10: 558
A11: 9 | B11: 45 | C11: 59 | D11: 490 | E11: 109 | F11: 990 | G11: 159 | H11: 1490 | I11: 209 | J11: 1990 | K11: 259 | L11: 2490 | M11: 309 | N11: 2990 | O11: 359 | P11: 3490 | Q11: 409 | R11: 4400 | S11: 459 | T11: 9900 | U11: 509 | W11: 559
A12: 10 | B12: 50 | C12: 60 | D12: 500 | E12: 110 | F12: 1000 | G12: 160 | H12: 1500 | I12: 210 | J12: 2000 | K12: 260 | L12: 2500 | M12: 310 | N12: 3000 | O12: 360 | P12: 3500 | Q12: 410 | R12: 4450 | S12: 460 | T12: 10000 | U12: 510 | W12: 560
A13: 11 | B13: 55 | C13: 61 | D13: 510 | E13: 111 | F13: 1010 | G13: 161 | H13: 1510 | I13: 211 | J13: 2010 | K13: 261 | L13: 2510 | M13: 311 | N13: 3010 | O13: 361 | P13: 3510 | Q13: 411 | R13: 4500 | S13: 461 | T13: 10200 | U13: 511 | W13: 561
A14: 12 | B14: 60 | C14: 62 | D14: 520 | E14: 112 | F14: 1020 | G14: 162 | H14: 1520 | I14: 212 | J14: 2020 | K14: 262 | L14: 2520 | M14: 312 | N14: 3020 | O14: 362 | P14: 3520 | Q14: 412 | R14: 4550 | S14: 462 | T14: 10400 | U14: 512 | W14: 562
A15: 13 | B15: 65 | C15: 63 | D15: 530 | E15: 113 | F15: 1030 | G15: 163 | H15: 1530 | I15: 213 | J15: 2030 | K15: 263 | L15: 2530 | M15: 313 | N15: 3030 | O15: 363 | P15: 3530 | Q15: 413 | R15: 4600 | S15: 463 | T15: 10600 | U15: 513 | W15: 563
A16: 14 | B16: 70 | C16: 64 | D16: 540 | E16: 114 | F16: 1040 | G16: 164 | H16: 1540 | I16: 214 | J16: 2040 | K16: 264 | L16: 2540 | M16: 314 | N16: 3040 | O16: 364 | P16: 3540 | Q16: 414 | R16: 4650 | S16: 464 | T16: 10800 | U16: 514 | W16: 564
A17: 15 | B17: 75 | C17: 65 | D17: 550 | E17: 115 | F17: 1050 | G17: 165 | H17: 1550 | I17: 215 | J17: 2050 | K17: 265 | L17: 2550 | M17: 315 | N17: 3050 | O17: 365 | P17: 3550 | Q17: 415 | R17: 4700 | S17: 465 | T17: 11000 | U17: 515 | W17: 565
A18: 16 | B18: 80 | C18: 66 | D18: 560 | E18: 116 | F18: 1060 | G18: 166 | H18: 1560 | I18: 216 | J18: 2060 | K18: 266 | L18: 2560 | M18: 316 | N18: 3060 | O18: 366 | P18: 3560 | Q18: 416 | R18: 4750 | S18: 466 | T18: 11300 | U18: 516 | W18: 566
A19: 17 | B19: 85 | C19: 67 | D19: 570 | E19: 117 | F19: 1070 | G19: 167 | H19: 1570 | I19: 217 | J19: 2070 | K19: 267 | L19: 2570 | M19: 317 | N19: 3070 | O19: 367 | P19: 3570 | Q19: 417 | R19: 4800 | S19: 467 | U19: 517 | W19: 567
A20: 18 | B20: 90 | C20: 68 | D20: 580 | E20: 118 | F20: 1080 | G20: 168 | H20: 1580 | I20: 218 | J20: 2080 | K20: 268 | L20: 2580 | M20: 318 | N20: 3080 | O20: 368 | P20: 3580 | Q20: 418 | R20: 4850 | S20: 468 | U20: 518 | W20: 568
A21: 19 | B21: 95 | C21: 69 | D21: 590 | E21: 119 | F21: 1090 | G21: 169 | H21: 1590 | I21: 219 | J21: 2090 | K21: 269 | L21: 2590 | M21: 319 | N21: 3090 | O21: 369 | P21: 3590 | Q21: 419 | R21: 4900 | S21: 469 | U21: 519 | W21: 569
A22: 20 | B22: 100 | C22: 70 | D22: 600 | E22: 120 | F22: 1100 | G22: 170 | H22: 1600 | I22: 220 | J22: 2100 | K22: 270 | L22: 2600 | M22: 320 | N22: 3100 | O22: 370 | P22: 3600 | Q22: 420 | R22: 5000 | S22: 470 | U22: 520 | W22: 570
A23: 21 | B23: 110 | C23: 71 | D23: 610 | E23: 121 | F23: 1110 | G23: 171 | H23: 1610 | I23: 221 | J23: 2110 | K23: 271 | L23: 2610 | M23: 321 | N23: 3110 | O23: 371 | P23: 3610 | Q23: 421 | R23: 5100 | S23: 471 | U23: 521 | W23: 571
A24: 22 | B24: 120 | C24: 72 | D24: 620 | E24: 122 | F24: 1120 | G24: 172 | H24: 1620 | I24: 222 | J24: 2120 | K24: 272 | L24: 2620 | M24: 322 | N24: 3120 | O24: 372 | P24: 3620 | Q24: 422 | R24: 5200 | S24: 472 | U24: 522 | W24: 572
A25: 23 | B25: 130 | C25: 73 | D25: 630 | E25: 123 | F25: 1130 | G25: 173 | H25: 1630 | I25: 223 | J25: 2130 | K25: 273 | L25: 2630 | M25: 323 | N25: 3130 | O25: 373 | P25: 3620 | Q25: 423 | R25: 5300 | S25: 473 | U25: 523 | W25: 573
A26: 24 | B26: 140 | C26: 74 | D26: 640 | E26: 124 | F26: 1140 | G26: 174 | H26: 1640 | I26: 224 | J26: 2140 | K26: 274 | L26: 2640 | M26: 324 | N26: 3140 | O26: 374 | P26: 3620 | Q26: 424 | R26: 5400 | S26: 474 | U26: 524 | W26: 574
A27: 25 | B27: 150 | C27: 75 | D27: 650 | E27: 125 | F27: 1150 | G27: 175 | H27: 1650 | I27: 225 | J27: 2150 | K27: 275 | L27: 2650 | M27: 325 | N27: 3150 | O27: 375 | P27: 3620 | Q27: 425 | R27: 5500 | S27: 475 | U27: 525 | W27: 575
A28: 26 | B28: 160 | C28: 76 | D28: 660 | E28: 126 | F28: 1160 | G28: 176 | H28: 1660 | I28: 226 | J28: 2160 | K28: 276 | L28: 2660 | M28: 326 | N28: 3160 | O28: 376 | P28: 3620 | Q28: 426 | R28: 5600 | S28: 476 | U28: 526 | W28: 576
A29: 27 | B29: 170 | C29: 77 | D29: 670 | E29: 127 | F29: 1170 | G29: 177 | H29: 1670 | I29: 227 | J29: 2170 | K29: 277 | L29: 2670 | M29: 327 | N29: 3170 | O29: 377 | P29: 3620 | Q29: 427 | S29: 477 | U29: 527 | W29: 577
A30: 28 | B30: 180 | C30: 78 | D30: 680 | E30: 128 | F30: 1180 | G30: 178 | H30: 1680 | I30: 228 | J30: 2180 | K30: 278 | L30: 2680 | M30: 328 | N30: 3180 | O30: 378 | P30: 3620 | Q30: 428 | S30: 478 | U30: 528 | W30: 578
A31: 29 | B31: 190 | C31: 79 | D31: 690 | E31: 129 | F31: 1190 | G31: 179 | H31: 1690 | I31: 229 | J31: 2190 | K31: 279 | L31: 2690 | M31: 329 | N31: 3190 | O31: 379 | P31: 3620 | Q31: 429 | S31: 479 | U31: 529 | W31: 579
A32: 30 | B32: 200 | C32: 80 | D32: 700 | E32: 130 | F32: 1200 | G32: 180 | H32: 1700 | I32: 230 | J32: 2200 | K32: 280 | L32: 2700 | M32: 330 | N32: 3200 | O32: 380 | P32: 3620 | Q32: 430 | S32: 480 | U32: 530 | W32: 580
A33: 31 | B33: 210 | C33: 81 | D33: 710 | E33: 131 | F33: 1210 | G33: 181 | H33: 1710 | I33: 231 | J33: 2210 | K33: 281 | L33: 2710 | M33: 331 | N33: 3210 | O33: 381 | P33: 3620 | Q33: 431 | S33: 481 | U33: 531 | W33: 581
A34: 32 | B34: 220 | C34: 82 | D34: 720 | E34: 132 | F34: 1220 | G34: 182 | H34: 1720 | I34: 232 | J34: 2220 | K34: 282 | L34: 2720 | M34: 332 | N34: 3220 | O34: 382 | P34: 3620 | Q34: 432 | S34: 482 | U34: 532 | W34: 582
A35: 33 | B35: 230 | C35: 83 | D35: 730 | E35: 133 | F35: 1230 | G35: 183 | H35: 1730 | I35: 233 | J35: 2230 | K35: 283 | L35: 2730 | M35: 333 | N35: 3230 | O35: 383 | P35: 3620 | Q35: 433 | S35: 483 | U35: 533 | W35: 583
A36: 34 | B36: 240 | C36: 84 | D36: 740 | E36: 134 | F36: 1240 | G36: 184 | H36: 1740 | I36: 234 | J36: 2240 | K36: 284 | L36: 2740 | M36: 334 | N36: 3240 | O36: 384 | P36: 3620 | Q36: 434 | S36: 484 | U36: 534 | W36: 584
A37: 35 | B37: 250 | C37: 85 | D37: 750 | E37: 135 | F37: 1250 | G37: 185 | H37: 1750 | I37: 235 | J37: 2250 | K37: 285 | L37: 2750 | M37: 335 | N37: 3250 | O37: 385 | P37: 3620 | Q37: 435 | S37: 485 | U37: 535 | W37: 585
A38: 36 | B38: 260 | C38: 86 | D38: 760 | E38: 136 | F38: 1260 | G38: 186 | H38: 1760 | I38: 236 | J38: 2260 | K38: 286 | L38: 2760 | M38: 336 | N38: 3260 | O38: 386 | P38: 3620 | Q38: 436 | S38: 486 | U38: 536 | W38: 586
A39: 37 | B39: 270 | C39: 87 | D39: 770 | E39: 137 | F39: 1270 | G39: 187 | H39: 1770 | I39: 237 | J39: 2270 | K39: 287 | L39: 2770 | M39: 337 | N39: 3270 | O39: 387 | P39: 3620 | Q39: 437 | S39: 487 | U39: 537 | W39: 587
A40: 38 | B40: 280 | C40: 88 | D40: 780 | E40: 138 | F40: 1280 | G40: 188 | H40: 1780 | I40: 238 | J40: 2280 | K40: 288 | L40: 2780 | M40: 338 | N40: 3280 | O40: 388 | P40: 3620 | Q40: 438 | S40: 488 | U40: 538 | W40: 588
...

Sheet Gems
B1: COLLECTION GEMS (Blue, Purple or Gold) | I1: GEMS SUMMARY
B2: Level | C2: Gems per Collection | D2: Level | E2: Gems per Collection | F2: Level | G2: Gems per Collection | I2: Level | J2: Gems per Collection
B3: 1 | C3: 5 | D3: 21 | E3: 1824 | F3: 41 | G3: 7469 | I3: 1 to 5 | J3: =SUM(C3:C6) -> 147
B4: 2 | C4: 22 | D4: 22 | E4: 2009 | F4: 42 | G4: 7863 | I4: 6 to 10 | J4: =SUM(C7:C11) -> 1077
B5: 3 | C5: 45 | D5: 23 | E5: 2204 | F5: 43 | G5: 8269 | I5: 11 to 15 | J5: =SUM(C12:C16) -> 2976
B6: 4 | C6: 75 | D6: 24 | E6: 2408 | F6: 44 | G6: 8686 | I6: 16 to 20 | J6: =SUM(C17:C21) -> 5954
B7: 5 | C7: 112 | D7: 25 | E7: 2623 | F7: 45 | G7: 9115 | I7: 21 to 25 | J7: =SUM(C22,E3:E6) -> 10094
B8: 6 | C8: 156 | D8: 26 | E8: 2847 | F8: 46 | G8: 9554 | I8: 26 to 30 | J8: =SUM(E7:E11) -> 15459
B9: 7 | C9: 208 | D9: 27 | E9: 3082 | F9: 47 | G9: 10005 | I9: 1 to 30 | J9: =SUM(J3:J8) -> 35707
B10: 8 | C10: 267 | D10: 28 | E10: 3326 | F10: 48 | G10: 10467 | I10: 31 to 35 | J10: =SUM(E12:E16) -> 22098
B11: 9 | C11: 334 | D11: 29 | E11: 3581 | F11: 49 | G11: 10941 | I11: 36 to 40 | J11: =SUM(E17:E21) -> 30057
B12: 10 | C12: 410 | D12: 30 | E12: 3847 | F12: 50 | G12: MAX | I12: 41 to 45 | J12: =SUM(E22,G3:G6) -> 39372
B13: 11 | C13: 494 | D13: 31 | E13: 4123 | I13: 46 to 50 | J13: =SUM(G7:G11) -> 50082
B14: 12 | C14: 586 | D14: 32 | E14: 4409 | I14: 31 to 50 | J14: =SUM(J10:J13) -> 141609
B15: 13 | C15: 688 | D15: 33 | E15: 4706 | I15: 1 to 50 | J15: =SUM(J9,J14) -> 177316
B16: 14 | C16: 798 | D16: 34 | E16: 5013
B17: 15 | C17: 916 | D17: 35 | E17: 5332
B18: 16 | C18: 1044 | D18: 36 | E18: 5661
B19: 17 | C19: 1182 | D19: 37 | E19: 6000
B20: 18 | C20: 1328 | D20: 38 | E20: 6351
B21: 19 | C21: 1484 | D21: 39 | E21: 6713
B22: 20 | C22: 1649 | D22: 40 | E22: 7085

Sheet Car Parts
A1: CAR VEHICULE UPGRADE PARTS | K1: CAR (Vehicle Advance Drawing)
A2: Rank | B2: Stars | C2: Phase 1 | D2: Phase 2 | E2: Phase 3 | F2: Phase 4 | G2: Phase 5 | H2: Total (per Part) | I2: All 04 Parts | K2: Rank | L2: Stars | M2: Drawings
A3: A | B3: 0 | C3: 10 | H3: =SUM(C3:G3) -> 10 | I3: =H3*4 -> 40 | K3: A | L3: 0 | M3: 4
A4: B | B4: 0 | C4: 20 | D4: 50 | H4: =SUM(C4:G4) -> 70 | I4: =H4*4 -> 280 | K4: B | L4: 0 | M4: 20
A5: B | B5: * | C5: 100 | D5: 120 | H5: =SUM(C5:G5) -> 220 | I5: =H5*4 -> 880 | K5: B | L5: * | M5: 80
A6: C | B6: 0 | C6: 240 | D6: 260 | E6: 280 | H6: =SUM(C6:G6) -> 780 | I6: =H6*4 -> 3120 | K6: C | L6: 0 | M6: 200
A7: C | B7: * | C7: 300 | D7: 320 | E7: 340 | H7: =SUM(C7:G7) -> 960 | I7: =H7*4 -> 3840 | K7: C | L7: * | M7: 500
A8: C | B8: ** | C8: 360 | D8: 380 | E8: 400 | H8: =SUM(C8:G8) -> 1140 | I8: =H8*4 -> 4560 | K8: C | L8: ** | M8: 1000
A9: D | B9: 0 | C9: 420 | D9: 440 | E9: 460 | F9: 480 | G9: 500 | H9: =SUM(C9:G9) -> 2300 | I9: =H9*4 -> 9200 | K9: D | L9: 0 | M9: 1200
A10: D | B10: * | C10: 520 | D10: 540 | E10: 560 | F10: 580 | G10: 600 | H10: =SUM(C10:G10) -> 2800 | I10: =H10*4 -> 11200 | K10: D | L10: * | M10: 1400
A11: D | B11: ** | C11: 620 | D11: 640 | E11: 660 | F11: 680 | G11: 700 | H11: =SUM(C11:G11) -> 3300 | I11: =H11*4 -> 13200 | K11: D | L11: ** | M11: 1800
A12: D | B12: *** | C12: 720 | D12: 740 | E12: 760 | F12: 780 | G12: 800 | H12: =SUM(C12:G12) -> 3800 | I12: =H12*4 -> 15200 | K12: D | L12: *** | M12: 2000
A13: E | B13: 0 | C13: 1100 | D13: 1130 | E13: 1160 | F13: 1190 | G13: 1220 | H13: =SUM(C13:G13) -> 5800 | I13: =H13*4 -> 23200 | K13: E | L13: 0 | M13: 2300
A14: E | B14: * | C14: 1250 | D14: 1280 | E14: 1310 | F14: 1340 | G14: 1370 | H14: =SUM(C14:G14) -> 6550 | I14: =H14*4 -> 26200 | K14: E | L14: * | M14: 2600
A15: E | B15: ** | C15: 1400 | D15: 1430 | E15: 1460 | F15: 1490 | G15: 1520 | H15: =SUM(C15:G15) -> 7300 | I15: =H15*4 -> 29200 | K15: E | L15: ** | M15: 2900
A16: E | B16: *** | C16: 1550 | D16: 1580 | E16: 1610 | F16: 1640 | G16: 1670 | H16: =SUM(C16:G16) -> 8050 | I16: =H16*4 -> 32200 | K16: E | L16: *** | M16: 3200
A17: E | B17: **** | C17: 1700 | D17: 1730 | E17: 1760 | F17: 1790 | G17: 1820 | H17: =SUM(C17:G17) -> 8800 | I17: =H17*4 -> 35200 | K17: E | L17: **** | M17: 3500
A18: E | B18: ***** | C18: 1850 | D18: 1880 | E18: 1910 | F18: 1940 | G18: 1970 | H18: =SUM(C18:G18) -> 9550 | I18: =H18*4 -> 38200 | K18: E | L18: ***** | M18: 4000
A19: S | B19: 0 | C19: 2000 | D19: 2030 | E19: 2060 | F19: 2090 | G19: 2120 | H19: =SUM(C19:G19) -> 10300 | I19: =H19*4 -> 41200 | K19: S | L19: 0 | M19: 4000
A20: S | B20: * | C20: 2150 | D20: 2180 | E20: 2210 | F20: 2240 | G20: 2270 | H20: =SUM(C20:G20) -> 11050 | I20: =H20*4 -> 44200 | K20: S | L20: * | M20: 4000
A21: S | B21: ** | C21: 2300 | D21: 2330 | E21: 2360 | F21: 2390 | G21: 2420 | H21: =SUM(C21:G21) -> 11800 | I21: =H21*4 -> 47200 | K21: S | L21: ** | M21: 4000
A22: S | B22: *** | C22: 2450 | D22: 2480 | E22: 2510 | F22: 2540 | G22: 2570 | H22: =SUM(C22:G22) -> 12550 | I22: =H22*4 -> 50200 | K22: S | L22: *** | M22: 4000
A23: S | B23: **** | C23: 2600 | D23: 2630 | E23: 2660 | F23: 2700 | G23: 2750 | H23: =SUM(C23:G23) -> 13340 | I23: =H23*4 -> 53360 | K23: S | L23: **** | M23: 4000
A24: S | B24: ***** | C24: 2800 | D24: 2850 | E24: 2900 | F24: 2950 | G24: 3000 | H24: =SUM(C24:G24) -> 14500 | I24: =H24*4 -> 58000 | K24: S | L24: ***** | M24: 8000
A25: SS | B25: 0 | C25: 3100 | D25: 3200 | E25: 3300 | F25: 3400 | G25: 3500 | H25: =SUM(C25:G25) -> 16500 | I25: =H25*4 -> 66000 | K25: SS | L25: 0 | M25: 8000
A26: SS | B26: * | C26: 3600 | D26: 3700 | E26: 3800 | F26: 3900 | G26: 4000 | H26: =SUM(C26:G26) -> 19000 | I26: =H26*4 -> 76000 | K26: SS | L26: * | M26: 11000
A27: SS | B27: ** | C27: 4100 | D27: 4200 | E27: 4300 | F27: 4400 | G27: 4500 | H27: =SUM(C27:G27) -> 21500 | I27: =H27*4 -> 86000 | K27: SS | L27: ** | M27: 11000
A28: SS | B28: *** | C28: 4600 | D28: 4700 | E28: 4800 | F28: 4900 | G28: 5000 | H28: =SUM(C28:G28) -> 24000 | I28: =H28*4 -> 96000 | K28: SS | L28: *** | M28: 15000
A29: SS | B29: **** | C29: 5200 | D29: 5400 | E29: 5600 | F29: 5800 | G29: 6000 | H29: =SUM(C29:G29) -> 28000 | I29: =H29*4 -> 112000 | K29: SS | L29: **** | M29: 15000
A30: SS | B30: ***** | C30: 6200 | D30: =6400 -> 6400 | E30: 6600 | F30: 6800 | G30: 7000 | H30: =SUM(C30:G30) -> 33000 | I30: =H30*4 -> 132000 | K30: SS | L30: ***** | M30: 20000
A31: SSS | B31: 0 | C31: 7300 | D31: 7600 | E31: 7900 | F31: 8200 | G31: 8500 | H31: =SUM(C31:G31) -> 39500 | I31: =H31*4 -> 158000 | K31: SSS | L31: 0 | M31: 20000
A32: SSS | B32: * | H32: =SUM(C32:G32) -> 0 | I32: =H32*4 -> 0 | K32: SSS | L32: *
A33: SSS | B33: ** | H33: =SUM(C33:G33) -> 0 | I33: =H33*4 -> 0 | K33: SSS | L33: **
A34: SSS | B34: *** | H34: =SUM(C34:G34) -> 0 | I34: =H34*4 -> 0 | K34: SSS | L34: ***
A35: SSS | B35: **** | H35: =SUM(C35:G35) -> 0 | I35: =H35*4 -> 0 | K35: SSS | L35: ****
A36: SSS | B36: ***** | H36: =SUM(C36:G36) -> 0 | I36: =H36*4 -> 0 | K36: SSS | L36: *****

Sheet Drones
A1: VILLA CONSTRUCTION DRONES | I1: VILLA DESIGN DRAFT
A2: Villa | B2: Hammers | C2: Gold Hammers | D2: Stages per Room | E2: Droids | F2: Droids per Room | G2: Droids (All 4 rooms) | I2: Villa | J2: Hammers | K2: Gold Hammers | L2: DRAFTS
A3: Classic Villa | B3: 1 | C3: 0 | D3: 5 | E3: 50 | F3: =D3*E3 -> 250 | G3: =F3*4 -> 1000 | I3: Classic Villa | J3: 1 | K3: 0 | L3: 200
A4: Elite Villa | B4: 1 | C4: 0 | D4: 10 | E4: 100 | F4: =D4*E4 -> 1000 | G4: =F4*4 -> 4000 | I4: Elite Villa | J4: 1 | K4: 0 | L4: 400
A5: Prestige Villa | B5: 2 | C5: 0 | D5: 10 | E5: 500 | F5: =D5*E5 -> 5000 | G5: =F5*4 -> 20000 | I5: Prestige Villa | J5: 2 | K5: 0 | L5: 600
B6: 2 | C6: 1 | D6: 10 | E6: 500 | F6: =D6*E6 -> 5000 | G6: =F6*4 -> 20000 | J6: 2 | K6: 1 | L6: 600
A7: Luxury Villa | B7: 4 | C7: 0 | D7: 10 | E7: 1000 | F7: =D7*E7 -> 10000 | G7: =F7*4 -> 40000 | I7: Luxury Villa | J7: 4 | K7: 0 | L7: 1000
B8: 4 | C8: 1 | D8: 10 | E8: 1000 | F8: =D8*E8 -> 10000 | G8: =F8*4 -> 40000 | J8: 4 | K8: 1 | L8: 1000
B9: 4 | C9: 2 | D9: 10 | E9: 1000 | F9: =D9*E9 -> 10000 | G9: =F9*4 -> 40000 | J9: 4 | K9: 2 | L9: 1000
B10: 4 | C10: 3 | D10: 10 | E10: 1000 | F10: =D10*E10 -> 10000 | G10: =F10*4 -> 40000 | J10: 4 | K10: 3 | L10: 1000
A11: Summit Villa | B11: 10 | C11: 0 | D11: 10 | E11: 1500 | F11: =D11*E11 -> 15000 | G11: =F11*4 -> 60000 | I11: Summit Villa | J11: 10 | K11: 0 | L11: 1500
B12: 10 | C12: 1 | D12: 10 | E12: 1500 | F12: =D12*E12 -> 15000 | G12: =F12*4 -> 60000 | J12: 10 | K12: 1 | L12: 1500
B13: 10 | C13: 2 | D13: 10 | E13: 1500 | F13: =D13*E13 -> 15000 | G13: =F13*4 -> 60000 | J13: 10 | K13: 2 | L13: 1500
B14: 10 | C14: 3 | D14: 10 | E14: 1500 | F14: =D14*E14 -> 15000 | G14: =F14*4 -> 60000 | J14: 10 | K14: 3 | L14: 1500
B15: 10 | C15: 4 | D15: 10 | E15: 1500 | F15: =D15*E15 -> 15000 | G15: =F15*4 -> 60000 | J15: 10 | K15: 4 | L15: 1500
B16: 10 | C16: 5 | D16: 10 | E16: 1500 | F16: =D16*E16 -> 15000 | G16: =F16*4 -> 60000 | J16: 10 | K16: 5 | L16: 1500
B17: 10 | C17: 6 | D17: 10 | E17: 1500 | F17: =D17*E17 -> 15000 | G17: =F17*4 -> 60000 | J17: 10 | K17: 6 | L17: 1500
B18: 10 | C18: 7 | D18: 10 | E18: 1500 | F18: =D18*E18 -> 15000 | G18: =F18*4 -> 60000 | J18: 10 | K18: 7 | L18: 1500
B19: 10 | C19: 8 | D19: 10 | E19: 1500 | F19: =D19*E19 -> 15000 | G19: =F19*4 -> 60000 | J19: 10 | K19: 8 | L19: 1500
B20: 10 | C20: 9 | D20: 10 | E20: 1500 | F20: =D20*E20 -> 15000 | G20: =F20*4 -> 60000 | J20: 10 | K20: 9 | L20: 1500
A21: Iconic Villa | B21: 10 | C21: 0 | D21: 10 | E21: 3000 | F21: =D21*E21 -> 30000 | G21: =F21*4 -> 120000 | I21: Iconic Villa | J21: 10 | K21: 0 | L21: 2000
B22: 10 | C22: 1 | D22: 10 | E22: 3000 | F22: =D22*E22 -> 30000 | G22: =F22*4 -> 120000 | J22: 10 | K22: 1 | L22: 2000
B23: 10 | C23: 2 | D23: 10 | E23: 3000 | F23: =D23*E23 -> 30000 | G23: =F23*4 -> 120000 | J23: 10 | K23: 2 | L23: 2000
B24: 10 | C24: 3 | D24: 10 | E24: 3000 | F24: =D24*E24 -> 30000 | G24: =F24*4 -> 120000 | J24: 10 | K24: 3 | L24: 2000
B25: 10 | C25: 4 | D25: 10 | E25: 3000 | F25: =D25*E25 -> 30000 | G25: =F25*4 -> 120000 | J25: 10 | K25: 4 | L25: 2000
B26: 10 | C26: 5 | D26: 10 | E26: 3000 | F26: =D26*E26 -> 30000 | G26: =F26*4 -> 120000 | J26: 10 | K26: 5 | L26: 2000
B27: 10 | C27: 6 | D27: 10 | E27: 3000 | F27: =D27*E27 -> 30000 | G27: =F27*4 -> 120000 | J27: 10 | K27: 6 | L27: 2000
B28: 10 | C28: 7 | D28: 10 | E28: 3000 | F28: =D28*E28 -> 30000 | G28: =F28*4 -> 120000 | J28: 10 | K28: 7 | L28: 2000
B29: 10 | C29: 8 | D29: 10 | E29: 3000 | F29: =D29*E29 -> 30000 | G29: =F29*4 -> 120000 | J29: 10 | K29: 8 | L29: 2000
B30: 10 | C30: 9 | D30: 10 | E30: 3000 | F30: =D30*E30 -> 30000 | G30: =F30*4 -> 120000 | J30: 10 | K30: 9 | L30: 2000
A31: Urban Heights | B31: 10 | C31: 0 | D31: 10 | E31: 6000 | F31: =D31*E31 -> 60000 | G31: =F31*4 -> 240000 | I31: Urban Heights | J31: 10 | K31: 0
B32: 10 | C32: 1 | D32: 10 | E32: 6000 | F32: =D32*E32 -> 60000 | G32: =F32*4 -> 240000 | J32: 10 | K32: 1
B33: 10 | C33: 2 | D33: 10 | E33: 6000 | F33: =D33*E33 -> 60000 | G33: =F33*4 -> 240000 | J33: 10 | K33: 2
B34: 10 | C34: 3 | D34: 10 | E34: 6000 | F34: =D34*E34 -> 60000 | G34: =F34*4 -> 240000 | J34: 10 | K34: 3
B35: 10 | C35: 4 | D35: 10 | E35: 6000 | F35: =D35*E35 -> 60000 | G35: =F35*4 -> 240000 | J35: 10 | K35: 4
B36: 10 | C36: 5 | D36: 10 | E36: 6000 | F36: =D36*E36 -> 60000 | G36: =F36*4 -> 240000 | J36: 10 | K36: 5
B37: 10 | C37: 6 | D37: 10 | E37: 6000 | F37: =D37*E37 -> 60000 | G37: =F37*4 -> 240000 | J37: 10 | K37: 6
B38: 10 | C38: 7 | D38: 10 | E38: 6000 | F38: =D38*E38 -> 60000 | G38: =F38*4 -> 240000 | J38: 10 | K38: 7
B39: 10 | C39: 8 | D39: 10 | E39: 6000 | F39: =D39*E39 -> 60000 | G39: =F39*4 -> 240000 | J39: 10 | K39: 8
B40: 10 | C40: 9 | D40: 10 | E40: 6000 | F40: =D40*E40 -> 60000 | G40: =F40*4 -> 240000 | J40: 10 | K40: 9
...

Sheet Floors,Exhibits,Homemaking,CarC
B1: Total Amounts (From Level 1 to 60) | L1: Total Amounts (From Level 1 to 60) | V1: From L 1 to 60 | X1: Total Amounts (From Level 38 to 60) | AF1: From L 1 to 60 | AH1: Total Amounts (From Level 38 to 60)
B2: =SUM(B6:B64) -> 1500 | C2: =SUM(C6:C64) -> 150 | D2: =SUM(D6:D64) -> 6000 | E2: =SUM(E6:E64) -> 600 | F2: =SUM(F6:F64) -> 30000 | G2: =SUM(G6:G64) -> 3000 | H2: Incomplete | L2: =SUM(L6:L64) -> 2000 | M2: =SUM(M6:M64) -> 200 | N2: =SUM(N6:N64) -> 8069 | O2: =SUM(O6:O64) -> 808 | P2: =SUM(P6:P64) -> 40345 | Q2: =SUM(Q6:Q64) -> 4040 | R2: =SUM(R6:R64) -> 1718 | S2: =SUM(S6:S64) -> 149 | ... W2: =SUM(W6:W64) -> 200 | X2: =SUM(X43:X64) -> 8000 | Y2: =SUM(Y43:Y64) -> 905 | Z2: =SUM(Z43:Z64) -> 40000 | AA2: =SUM(AA43:AA64) -> 4525 | AB2: =SUM(AB43:AB64) -> 1600 | AC2: =SUM(AC43:AC64) -> 181 | AD2: =SUM(AD43:AD64) -> 8000 | AE2: =SUM(AE43:AE64) -> 905 | AF2: =SUM(AF6:AF64) -> 2000 | AG2: =SUM(AG6:AG64) -> 200 | AH2: =SUM(AH43:AH64) -> 8000 | AI2: =SUM(AI43:AI64) -> 905 | AJ2: =SUM(AJ43:AJ64) -> 40000 | AK2: =SUM(AK43:AK64) -> 4525 | AL2: =SUM(AL43:AL64) -> 1600 | AM2: =SUM(AM43:AM64) -> 181 | AN2: =SUM(AN43:AN64) -> 8000 | AO2: =SUM(AO43:AO64) -> 905
B3: HQ FLOORS (01 Object of the Room) | L3: PRIVATE MUSEUM (01 Object of the room) | V3: HOMEMAKING (01 Girl only) | AF3: CAR CORE (01 part of the car)
B4: Floor 1 | D4: F2 | F4: F3 | H4: F4 | J4: F5 | L4: Room 1 | N4: R2 | P4: R3 | R4: R4 | T4: R5 | V4: Tier 1 | X4: T2 | Z4: T3 | AB4: T4 | AD4: T5 | AF4: D Grade | AH4: C | AJ4: B | AL4: A | AN4: A+
A5: Level | B5: Wood | C5: Steel | D5: Wood | E5: Steel | F5: Wood | G5: Steel | H5: HQ Wood | I5: HQ Steel | J5: HQ Wood | K5: HQ Steel | L5: Sandstone | M5: Tile | N5: Sandstone | O5: Tile | P5: Sandstone | Q5: Tile | R5: HQ Sandstone | S5: HQ Tile | T5: HQ Sandstone | U5: HQ Tile | V5: Coins | W5: Keys | X5: Coins | Y5: Keys | Z5: Coins | AA5: Keys | AB5: HQ Coins | AC5: HQ Keys | AD5: HQ Coins | AE5: HQ Keys | AF5: Plug | AG5: Coil | AH5: Plug | AI5: Coil | AJ5: Plug | AK5: Coil | AL5: Enhanced Plug | AM5: Enhanced Coil | AN5: Enhanced Plug | AO5: Enhanced Coil
A6: 1 | B6: 1 | C6: 0 | D6: 4 | E6: 0 | F6: 20 | G6: 0 | H6: 1 | I6: 0 | J6: 5 | K6: 0 | L6: 1 | M6: 0 | N6: 5 | O6: 0 | P6: 25 | Q6: 0 | R6: 1 | S6: 0 | T6: 5 | U6: 0 | V6: 1 | W6: 0 | X6: 5 | Y6: 0 | Z6: 25 | AA6: 0 | AB6: 1 | AC6: 0 | AD6: 5 | AE6: 0 | AF6: 1 | AG6: 0 | AH6: 5 | AI6: 0 | AJ6: 25 | AK6: 0 | AL6: 1 | AM6: 0 | AN6: 5 | AO6: 0
A7: 2 | B7: 2 | C7: 0 | D7: 8 | E7: 0 | F7: 40 | G7: 0 | H7: 2 | I7: 0 | J7: 10 | K7: 0 | L7: 2 | M7: 0 | N7: 10 | O7: 0 | P7: 50 | Q7: 0 | R7: 2 | S7: 0 | T7: =R7*5 -> 10 | U7: =S7*5 -> 0 | V7: 2 | W7: 0 | X7: 10 | Y7: 0 | Z7: 50 | AA7: 0 | AB7: 2 | AC7: 0 | AD7: 10 | AE7: 0 | AF7: 2 | AG7: 0 | AH7: 10 | AI7: 0 | AJ7: 50 | AK7: 0 | AL7: 2 | AM7: 0 | AN7: 10 | AO7: 0
A8: 3 | B8: 2 | C8: 0 | D8: 8 | E8: 0 | F8: 40 | G8: 0 | H8: 2 | I8: 0 | J8: 10 | K8: 0 | L8: 2 | M8: 0 | N8: 10 | O8: 0 | P8: 50 | Q8: 0 | R8: 2 | S8: 0 | T8: =R8*5 -> 10 | U8: =S8*5 -> 0 | V8: 2 | W8: 0 | X8: 10 | Y8: 0 | Z8: 50 | AA8: 0 | AB8: 2 | AC8: 0 | AD8: 10 | AE8: 0 | AF8: 2 | AG8: 0 | AH8: 10 | AI8: 0 | AJ8: 50 | AK8: 0 | AL8: 2 | AM8: 0 | AN8: 10 | AO8: 0
A9: 4 | B9: 2 | C9: 0 | D9: 8 | E9: 0 | F9: 40 | G9: 0 | H9: 2 | I9: 0 | J9: 10 | K9: 0 | L9: 2 | M9: 0 | N9: 12 | O9: 0 | P9: 60 | Q9: 0 | R9: 2 | S9: 0 | T9: =R9*5 -> 10 | U9: =S9*5 -> 0 | V9: 2 | W9: 0 | X9: 10 | Y9: 0 | Z9: 50 | AA9: 0 | AB9: 2 | AC9: 0 | AD9: 10 | AE9: 0 | AF9: 2 | AG9: 0 | AH9: 10 | AI9: 0 | AJ9: 50 | AK9: 0 | AL9: 2 | AM9: 0 | AN9: 10 | AO9: 0
A10: 5 | B10: 2 | C10: 0 | D10: 8 | E10: 0 | F10: 40 | G10: 0 | H10: 2 | I10: 0 | J10: 10 | K10: 0 | L10: 3 | M10: 0 | N10: 12 | O10: 0 | P10: 60 | Q10: 0 | R10: 3 | S10: 0 | T10: =R10*5 -> 15 | U10: =S10*5 -> 0 | V10: 3 | W10: 0 | X10: 15 | Y10: 0 | Z10: 75 | AA10: 0 | AB10: 3 | AC10: 0 | AD10: 15 | AE10: 0 | AF10: 3 | AG10: 0 | AH10: 15 | AI10: 0 | AJ10: 75 | AK10: 0 | AL10: 3 | AM10: 0 | AN10: 15 | AO10: 0
A11: 6 | B11: 3 | C11: 0 | D11: 12 | E11: 0 | F11: 60 | G11: 0 | H11: 2 | I11: 0 | J11: 10 | K11: 0 | L11: 4 | M11: 0 | N11: 16 | O11: 0 | P11: 80 | Q11: 0 | R11: 3 | S11: 0 | T11: =R11*5 -> 15 | U11: =S11*5 -> 0 | V11: 4 | W11: 0 | X11: 20 | Y11: 0 | Z11: 100 | AA11: 0 | AB11: 4 | AC11: 0 | AD11: 20 | AE11: 0 | AF11: 4 | AG11: 0 | AH11: 20 | AI11: 0 | AJ11: 100 | AK11: 0 | AL11: 4 | AM11: 0 | AN11: 20 | AO11: 0
A12: 7 | B12: 4 | C12: 0 | D12: 16 | E12: 0 | F12: 80 | G12: 0 | H12: 3 | I12: 0 | J12: 15 | K12: 0 | L12: 5 | M12: 0 | N12: 16 | O12: 0 | P12: 80 | Q12: 0 | R12: 3 | S12: 0 | T12: =R12*5 -> 15 | U12: =S12*5 -> 0 | V12: 5 | W12: 0 | X12: 25 | Y12: 0 | Z12: 125 | AA12: 0 | AB12: 5 | AC12: 0 | AD12: 25 | AE12: 0 | AF12: 5 | AG12: 0 | AH12: 25 | AI12: 0 | AJ12: 125 | AK12: 0 | AL12: 5 | AM12: 0 | AN12: 25 | AO12: 0
A13: 8 | B13: 4 | C13: 0 | D13: 16 | E13: 0 | F13: 80 | G13: 0 | H13: 3 | I13: 0 | J13: 15 | K13: 0 | L13: 5 | M13: 0 | N13: 20 | O13: 0 | P13: 100 | Q13: 0 | R13: 4 | S13: 0 | T13: =R13*5 -> 20 | U13: =S13*5 -> 0 | V13: 5 | W13: 0 | X13: 25 | Y13: 0 | Z13: 125 | AA13: 0 | AB13: 5 | AC13: 0 | AD13: 25 | AE13: 0 | AF13: 5 | AG13: 0 | AH13: 25 | AI13: 0 | AJ13: 125 | AK13: 0 | AL13: 5 | AM13: 0 | AN13: 25 | AO13: 0
A14: 9 | B14: 4 | C14: 0 | D14: 16 | E14: 0 | F14: 80 | G14: 0 | H14: 3 | I14: 0 | J14: 15 | K14: 0 | L14: 5 | M14: 0 | N14: 20 | O14: 0 | P14: 100 | Q14: 0 | R14: 4 | S14: 0 | T14: =R14*5 -> 20 | U14: =S14*5 -> 0 | V14: 5 | W14: 0 | X14: 25 | Y14: 0 | Z14: 125 | AA14: 0 | AB14: 5 | AC14: 0 | AD14: 25 | AE14: 0 | AF14: 5 | AG14: 0 | AH14: 25 | AI14: 0 | AJ14: 125 | AK14: 0 | AL14: 5 | AM14: 0 | AN14: 25 | AO14: 0
A15: 10 | B15: 4 | C15: 0 | D15: 16 | E15: 0 | F15: 80 | G15: 0 | H15: 3 | I15: 0 | J15: 15 | K15: 0 | L15: 5 | M15: 0 | N15: 24 | O15: 0 | P15: 120 | Q15: 0 | R15: 4 | S15: 0 | T15: =R15*5 -> 20 | U15: =S15*5 -> 0 | V15: 5 | W15: 0 | X15: 25 | Y15: 0 | Z15: 125 | AA15: 0 | AB15: 5 | AC15: 0 | AD15: 25 | AE15: 0 | AF15: 5 | AG15: 0 | AH15: 25 | AI15: 0 | AJ15: 125 | AK15: 0 | AL15: 5 | AM15: 0 | AN15: 25 | AO15: 0
A16: 11 | B16: 5 | C16: 0 | D16: 20 | E16: 0 | F16: 100 | G16: 0 | H16: 4 | I16: 0 | J16: 20 | K16: 0 | L16: 6 | M16: 0 | N16: 24 | O16: 0 | P16: 120 | Q16: 0 | R16: 5 | S16: 0 | T16: =R16*5 -> 25 | U16: =S16*5 -> 0 | V16: 6 | W16: 0 | X16: 30 | Y16: 0 | Z16: 150 | AA16: 0 | AB16: 6 | AC16: 0 | AD16: 30 | AE16: 0 | AF16: 6 | AG16: 0 | AH16: 30 | AI16: 0 | AJ16: 150 | AK16: 0 | AL16: 6 | AM16: 0 | AN16: 30 | AO16: 0
A17: 12 | B17: 5 | C17: 0 | D17: 20 | E17: 0 | F17: 100 | G17: 0 | H17: 4 | I17: 0 | J17: 20 | K17: 0 | L17: 6 | M17: 0 | N17: 28 | O17: 0 | P17: 140 | Q17: 0 | R17: 5 | S17: 0 | T17: =R17*5 -> 25 | U17: =S17*5 -> 0 | V17: 6 | W17: 0 | X17: 30 | Y17: 0 | Z17: 150 | AA17: 0 | AB17: 6 | AC17: 0 | AD17: 30 | AE17: 0 | AF17: 6 | AG17: 0 | AH17: 30 | AI17: 0 | AJ17: 150 | AK17: 0 | AL17: 6 | AM17: 0 | AN17: 30 | AO17: 0
A18: 13 | B18: 5 | C18: 0 | D18: 20 | E18: 0 | F18: 100 | G18: 0 | H18: 4 | I18: 0 | J18: 20 | K18: 0 | L18: 6 | M18: 0 | N18: 28 | O18: 0 | P18: 140 | Q18: 0 | R18: 5 | S18: 0 | T18: =R18*5 -> 25 | U18: =S18*5 -> 0 | V18: 6 | W18: 0 | X18: 30 | Y18: 0 | Z18: 150 | AA18: 0 | AB18: 6 | AC18: 0 | AD18: 30 | AE18: 0 | AF18: 6 | AG18: 0 | AH18: 30 | AI18: 0 | AJ18: 150 | AK18: 0 | AL18: 6 | AM18: 0 | AN18: 30 | AO18: 0
... A60: 55 | B60: 80 | C60: 8 | D60: 320 | E60: 32 | F60: 1600 | G60: 160 | H60: 64 | I60: 6 | J60: 320 | K60: 30 | L60: 105 | M60: 11 | N60: 420 | O60: 44 | P60: 2100 | Q60: 220 | R60: 70 | S60: 7 | T60: =R60*5 -> 350 | U60: =S60*5 -> 35 | V60: 105 | W60: 11 | X60: 525 | Y60: 55 | Z60: 2625 | AA60: 275 | AB60: 105 | AC60: 11 | AD60: 525 | AE60: 55 | AF60: 105 | AG60: 11 | AH60: 525 | AI60: 55 | AJ60: 2625 | AK60: 275 | AL60: 105 | AM60: 11 | AN60: 525 | AO60: 55
A61: 56 | B61: 80 | C61: 8 | D61: 320 | E61: 32 | F61: 1600 | G61: 160 | L61: 105 | M61: 11 | N61: 420 | O61: 44 | P61: 2100 | Q61: 220 | R61: 80 | S61: 8 | T61: =R61*5 -> 400 | U61: =S61*5 -> 40 | V61: 105 | W61: 11 | X61: 525 | Y61: 55 | Z61: 2625 | AA61: 275 | AB61: 105 | AC61: 11 | AD61: 525 | AE61: 55 | AF61: 105 | AG61: 11 | AH61: 525 | AI61: 55 | AJ61: 2625 | AK61: 275 | AL61: 105 | AM61: 11 | AN61: 525 | AO61: 55
A62: 57 | B62: 90 | C62: 9 | D62: 360 | E62: 36 | F62: 1800 | G62: 180 | L62: 120 | M62: 12 | N62: 480 | O62: 48 | P62: 2400 | Q62: 240 | R62: 80 | S62: 8 | T62: =R62*5 -> 400 | U62: =S62*5 -> 40 | V62: 120 | W62: 12 | X62: 600 | Y62: 60 | Z62: 3000 | AA62: 300 | AB62: 120 | AC62: 12 | AD62: 600 | AE62: 60 | AF62: 120 | AG62: 12 | AH62: 600 | AI62: 60 | AJ62: 3000 | AK62: 300 | AL62: 120 | AM62: 12 | AN62: 600 | AO62: 60
A63: 58 | B63: 100 | C63: 9 | D63: 400 | E63: 36 | F63: 2000 | G63: 180 | H63: 80 | I63: 7 | J63: 400 | K63: 35 | L63: 135 | M63: 13 | N63: 540 | O63: 54 | P63: 2700 | Q63: 270 | R63: 80 | S63: 8 | T63: =R63*5 -> 400 | U63: =S63*5 -> 40 | V63: 135 | W63: 13 | X63: 675 | Y63: 65 | Z63: 3375 | AA63: 325 | AB63: 135 | AC63: 13 | AD63: 675 | AE63: 65 | AF63: 135 | AG63: 13 | AH63: 675 | AI63: 65 | AJ63: 3375 | AK63: 325 | AL63: 135 | AM63: 13 | AN63: 675 | AO63: 65
A64: 59 | B64: 100 | C64: 9 | D64: 400 | E64: 36 | F64: 2000 | G64: 180 | L64: 150 | M64: 14 | N64: 600 | O64: 60 | P64: 3000 | Q64: 300 | R64: 100 | S64: 10 | T64: =R64*5 -> 500 | U64: =S64*5 -> 50 | V64: 150 | W64: 14 | X64: 750 | Y64: 70 | Z64: 3750 | AA64: 350 | AB64: 150 | AC64: 14 | AD64: 750 | AE64: 70 | AF64: 150 | AG64: 14 | AH64: 750 | AI64: 70 | AJ64: 3750 | AK64: 350 | AL64: 150 | AM64: 14 | AN64: 750 | AO64: 70
A65: 60 | B65: MAX | L65: MAX | V65: MAX | AF65: MAX

Sheet Assets
A1: ASSET COINS | O1: ASSET COINS SUMMARY
A2: BASIC GOLD ASSETS | F2: ABROAD ADVENTURES ASSETS | K2: AUCTION ASSETS | P2: BASIC ASSETS | S2: ABROAD ADVENTURES ASSETS | V2: AUCTION ASSETS
A3: Level | B3: Jewelry | C3: Car | D3: Property | F3: Level | G3: Jewelry | H3: Car | I3: Property | K3: Level | L3: Car | M3: Property | O3: Levels | P3: Jewelry | Q3: Car | R3: Property | S3: Jewelry | T3: Car | U3: Property | V3: Car | W3: Property
A4: 1 | B4: 500 | C4: 1000 | D4: 2000 | F4: 1 | G4: 1000 | H4: 1500 | I4: 3000 | K4: 1 | L4: 2000 | M4: 4000 | O4: 1 to 15 | P4: =SUM(B4:B17) -> 48500 | Q4: =SUM(C4:C17) -> 97000 | R4: =SUM(D4:D17) -> 194000 | S4: =SUM(G4:G17) -> 97000 | T4: =SUM(H4:H17) -> 145500 | U4: =SUM(I4:I17) -> 291000 | V4: =SUM(L4:L17) -> 194000 | W4: =SUM(M4:M17) -> 388000
A5: 2 | B5: 750 | C5: 1500 | D5: 3000 | F5: 2 | G5: 1500 | H5: 2250 | I5: 4500 | K5: 2 | L5: 3000 | M5: 6000 | O5: 16 to 20 | P5: =SUM(B18:B22) -> 90500 | Q5: =SUM(C18:C22) -> 181000 | R5: =SUM(D18:D22) -> 362000 | S5: =SUM(G18:G22) -> 181000 | T5: =SUM(H18:H22) -> 271500 | U5: =SUM(I18:I22) -> 543000 | V5: =SUM(L18:L22) -> 362000 | W5: =SUM(M18:M22) -> 724000
A6: 3 | B6: 1000 | C6: 2000 | D6: 4000 | F6: 3 | G6: 2000 | H6: 3000 | I6: 6000 | K6: 3 | L6: 4000 | M6: 8000 | O6: 21 to 25 | P6: =SUM(B23:B27) -> 165000 | Q6: =SUM(C23:C27) -> 330000 | R6: =SUM(D23:D27) -> 660000 | S6: =SUM(G23:G27) -> 330000 | T6: =SUM(H23:H27) -> 495000 | U6: =SUM(I23:I27) -> 990000 | V6: =SUM(L23:L27) -> 660000 | W6: =SUM(M23:M27) -> 1320000
A7: 4 | B7: 1250 | C7: 2500 | D7: 5000 | F7: 4 | G7: 2500 | H7: 3750 | I7: 7500 | K7: 4 | L7: 5000 | M7: 10000 | O7: 26 to 30 | P7: =SUM(B28:B32) -> 252000 | Q7: =SUM(C28:C32) -> 504000 | R7: =SUM(D28:D32) -> 1008000 | S7: =SUM(G28:G32) -> 504000 | T7: =SUM(H28:H32) -> 756000 | U7: =SUM(I28:I32) -> 1512000 | V7: =SUM(L28:L32) -> 1008000 | W7: =SUM(M28:M32) -> 2016000
A8: 5 | B8: 1500 | C8: 3000 | D8: 6000 | F8: 5 | G8: 3000 | H8: 4500 | I8: 9000 | K8: 5 | L8: 6000 | M8: 12000 | O8: 1 to 30 | P8: =SUM(P4:P7) -> 556000 | Q8: =SUM(Q4:Q7) -> 1112000 | R8: =SUM(R4:R7) -> 2224000 | S8: =SUM(S4:S7) -> 1112000 | T8: =SUM(T4:T7) -> 1668000 | U8: =SUM(U4:U7) -> 3336000 | V8: =SUM(V4:V7) -> 2224000 | W8: =SUM(W4:W7) -> 4448000
A9: 6 | B9: 2000 | C9: 4000 | D9: 8000 | F9: 6 | G9: 4000 | H9: 6000 | I9: 12000 | K9: 6 | L9: 8000 | M9: 16000 | O9: 31 to 35 | P9: =SUM(B33:B37) -> 337500 | Q9: =SUM(C33:C37) -> 675000 | R9: =SUM(D33:D37) -> 1350000 | S9: =SUM(G33:G37) -> 675000 | T9: =SUM(H33:H37) -> 1012500 | U9: =SUM(I33:I37) -> 2025000 | V9: =SUM(L33:L37) -> 1350000 | W9: =SUM(M33:M37) -> 2700000
A10: 7 | B10: 2500 | C10: 5000 | D10: 10000 | F10: 7 | G10: 5000 | H10: 7500 | I10: 15000 | K10: 7 | L10: 10000 | M10: 20000 | O10: 36 to 40 | P10: =SUM(B38:B42) -> 400000 | Q10: =SUM(C38:C42) -> 800000 | R10: =SUM(D38:D42) -> 1600000 | S10: =SUM(G38:G42) -> 800000 | T10: =SUM(H38:H42) -> 1200000 | U10: =SUM(I38:I42) -> 2400000 | V10: =SUM(L38:L42) -> 1600000 | W10: =SUM(M38:M42) -> 3200000
A11: 8 | B11: 3000 | C11: 6000 | D11: 12000 | F11: 8 | G11: 6000 | H11: 9000 | I11: 18000 | K11: 8 | L11: 12000 | M11: 24000 | O11: 41 to 45 | P11: =SUM(B43:B47) -> 462500 | Q11: =SUM(C43:C47) -> 925000 | R11: =SUM(D43:D47) -> 1850000 | S11: =SUM(G43:G47) -> 925000 | T11: =SUM(H43:H47) -> 1387500 | U11: =SUM(I43:I47) -> 2775000 | V11: =SUM(L43:L47) -> 1850000 | W11: =SUM(M43:M47) -> 3700000
A12: 9 | B12: 3500 | C12: 7000 | D12: 14000 | F12: 9 | G12: 7000 | H12: 10500 | I12: 21000 | K12: 9 | L12: 14000 | M12: 28000 | O12: 46 to 50 | P12: =SUM(B48:B52) -> 525000 | Q12: =SUM(C48:C52) -> 1050000 | R12: =SUM(D48:D52) -> 2100000 | S12: =SUM(G48:G52) -> 1050000 | T12: =SUM(H48:H52) -> 1575000 | U12: =SUM(I48:I52) -> 3150000 | V12: =SUM(L48:L52) -> 2100000 | W12: =SUM(M48:M52) -> 4200000
A13: 10 | B13: 4000 | C13: 8000 | D13: 16000 | F13: 10 | G13: 8000 | H13: 12000 | I13: 24000 | K13: 10 | L13: 16000 | M13: 32000 | O13: 51 to 55 | P13: =SUM(B53:B57) -> 587500 | Q13: =SUM(C53:C57) -> 1175000 | R13: =SUM(D53:D57) -> 2350000 | S13: =SUM(G53:G57) -> 1175000 | T13: =SUM(H53:H57) -> 1762500 | U13: =SUM(I53:I57) -> 3525000 | V13: =SUM(L53:L57) -> 2350000 | W13: =SUM(M53:M57) -> 4700000
A14: 11 | B14: 5000 | C14: 10000 | D14: 20000 | F14: 11 | G14: 10000 | H14: 15000 | I14: 30000 | K14: 11 | L14: 20000 | M14: 40000 | O14: 56 to 60 | P14: =SUM(B58:B62) -> 650000 | Q14: =SUM(C58:C62) -> 1300000 | R14: =SUM(D58:D62) -> 2600000 | S14: =SUM(G58:G62) -> 1300000 | T14: =SUM(H58:H62) -> 1950000 | U14: =SUM(I58:I62) -> 3900000 | V14: =SUM(L58:L62) -> 2600000 | W14: =SUM(M58:M62) -> 5200000
A15: 12 | B15: 6000 | C15: 12000 | D15: 24000 | F15: 12 | G15: 12000 | H15: 18000 | I15: 36000 | K15: 12 | L15: 24000 | M15: 48000 | O15: 31 to 60 | P15: =SUM(P9:P14) -> 2962500 | Q15: =SUM(Q9:Q14) -> 5925000 | R15: =SUM(R9:R14) -> 11850000 | S15: =SUM(S9:S14) -> 5925000 | T15: =SUM(T9:T14) -> 8887500 | U15: =SUM(U9:U14) -> 17775000 | V15: =SUM(V9:V14) -> 11850000 | W15: =SUM(W9:W14) -> 23700000
A16: 13 | B16: 7500 | C16: 15000 | D16: 30000 | F16: 13 | G16: 15000 | H16: 22500 | I16: 45000 | K16: 13 | L16: 30000 | M16: 60000 | O16: 1 to 60 | P16: =P8+P15 -> 3518500 | Q16: =Q8+Q15 -> 7037000 | R16: =R8+R15 -> 14074000 | S16: =S8+S15 -> 7037000 | T16: =T8+T15 -> 10555500 | U16: =U8+U15 -> 21111000 | V16: =V8+V15 -> 14074000 | W16: =W8+W15 -> 28148000
A17: 14 | B17: 10000 | C17: 20000 | D17: 40000 | F17: 14 | G17: 20000 | H17: 30000 | I17: 60000 | K17: 14 | L17: 40000 | M17: 80000
A18: 15 | B18: 12500 | C18: 25000 | D18: 50000 | F18: 15 | G18: 25000 | H18: 37500 | I18: 75000 | K18: 15 | L18: 50000 | M18: 100000 | O18: PROMOTION COST (ASSETS REQUIRED)
A19: 16 | B19: 15000 | C19: 30000 | D19: 60000 | F19: 16 | G19: 30000 | H19: 45000 | I19: 90000 | K19: 16 | L19: 60000 | M19: 120000 | O19: Level | P19: New Max Level | Q19: Assets Req.
A20: 17 | B20: 18000 | C20: 36000 | D20: 72000 | F20: 17 | G20: 36000 | H20: 54000 | I20: 108000 | K20: 17 | L20: 72000 | M20: 144000 | O20: 30 | P20: 35 | Q20: 1
A21: 18 | B21: 21000 | C21: 42000 | D21: 84000 | F21: 18 | G21: 42000 | H21: 63000 | I21: 126000 | K21: 18 | L21: 84000 | M21: 168000 | O21: 35 | P21: 40 | Q21: 1
A22: 19 | B22: 24000 | C22: 48000 | D22: 96000 | F22: 19 | G22: 48000 | H22: 72000 | I22: 144000 | K22: 19 | L22: 96000 | M22: 192000 | O22: 40 | P22: 45 | Q22: 1
A23: 20 | B23: 27000 | C23: 54000 | D23: 108000 | F23: 20 | G23: 54000 | H23: 81000 | I23: 162000 | K23: 20 | L23: 108000 | M23: 216000 | O23: 45 | P23: 50 | Q23: 2
A24: 21 | B24: 30000 | C24: 60000 | D24: 120000 | F24: 21 | G24: 60000 | H24: 90000 | I24: 180000 | K24: 21 | L24: 120000 | M24: 240000 | O24: 50 | P24: 55 | Q24: 2
A25: 22 | B25: 33000 | C25: 66000 | D25: 132000 | F25: 22 | G25: 66000 | H25: 99000 | I25: 198000 | K25: 22 | L25: 132000 | M25: 264000 | O25: 55 | P25: 60 | Q25: 3
A26: 23 | B26: 36000 | C26: 72000 | D26: 144000 | F26: 23 | G26: 72000 | H26: 108000 | I26: 216000 | K26: 23 | L26: 144000 | M26: 288000
A27: 24 | B27: 39000 | C27: 78000 | D27: 156000 | F27: 24 | G27: 78000 | H27: 117000 | I27: 234000 | K27: 24 | L27: 156000 | M27: 312000
A28: 25 | B28: 42000 | C28: 84000 | D28: 168000 | F28: 25 | G28: 84000 | H28: 126000 | I28: 252000 | K28: 25 | L28: 168000 | M28: 336000
A29: 26 | B29: 45000 | C29: 90000 | D29: 180000 | F29: 26 | G29: 90000 | H29: 135000 | I29: 270000 | K29: 26 | L29: 180000 | M29: 360000
A30: 27 | B30: 50000 | C30: 100000 | D30: 200000 | F30: 27 | G30: 100000 | H30: 150000 | I30: 300000 | K30: 27 | L30: 200000 | M30: 400000
A31: 28 | B31: 55000 | C31: 110000 | D31: 220000 | F31: 28 | G31: 110000 | H31: 165000 | I31: 330000 | K31: 28 | L31: 220000 | M31: 440000
A32: 29 | B32: 60000 | C32: 120000 | D32: 240000 | F32: 29 | G32: 120000 | H32: 180000 | I32: 360000 | K32: 29 | L32: 240000 | M32: 480000
A33: 30 | B33: 62500 | C33: 125000 | D33: 250000 | F33: 30 | G33: 125000 | H33: 187500 | I33: 375000 | K33: 30 | L33: 250000 | M33: 500000
A34: 31 | B34: 65000 | C34: 130000 | D34: 260000 | F34: 31 | G34: 130000 | H34: 195000 | I34: 390000 | K34: 31 | L34: 260000 | M34: 520000
A35: 32 | B35: 67500 | C35: 135000 | D35: 270000 | F35: 32 | G35: 135000 | H35: 202500 | I35: 405000 | K35: 32 | L35: 270000 | M35: 540000
A36: 33 | B36: 70000 | C36: 140000 | D36: 280000 | F36: 33 | G36: 140000 | H36: 210000 | I36: 420000 | K36: 33 | L36: 280000 | M36: 560000
A37: 34 | B37: 72500 | C37: 145000 | D37: 290000 | F37: 34 | G37: 145000 | H37: 217500 | I37: 435000 | K37: 34 | L37: 290000 | M37: 580000
... A62: 59 | B62: 135000 | C62: 270000 | D62: 540000 | F62: 59 | G62: 270000 | H62: 405000 | I62: 810000 | K62: 59 | L62: 540000 | M62: 1080000
A63: 60 | B63: MAX | C63: MAX | D63: MAX | F63: 60 | G63: MAX | H63: MAX | I63: MAX | K63: 60 | L63: MAX | M63: MAX

Sheet Artist
A1: ARTIST EXP CARDS (per level) | L1: ARTIST EXP CARDS AND PROMOTION CARDS
A2: Level | B2: EXP | C2: Level | D2: EXP | E2: Level | F2: EXP | G2: Level | H2: EXP | I2: Level | J2: EXP | L2: Levels | M2: EXP | N2: Promotion Cards | O2: EXP Accum | P2: Promotion Cards Accum
C3: 30 | D3: 65000 | E3: 60 | F3: 1000000 | G3: 90 | H3: 3100000 | I3: 120 | J3: 6100000 | L3: 1 to 20 | M3: 70600 | O3: 70600
A4: 1 | B4: 100 | C4: 31 | D4: 70000 | E4: 61 | F4: 1050000 | G4: 91 | H4: 3200000 | I4: 121 | J4: 6200000 | L4: 21 to 30 | M4: 293000 | N4: 50 | O4: 363600 | P4: 50
A5: 2 | B5: 200 | C5: 32 | D5: 75000 | E5: 62 | F5: 1100000 | G5: 92 | H5: 3300000 | I5: 122 | J5: 6300000 | L5: 31 to 40 | M5: 920000 | N5: 100 | O5: 1283600 | P5: 150
A6: 3 | B6: 300 | C6: 33 | D6: 80000 | E6: 63 | F6: 1150000 | G6: 93 | H6: 3400000 | I6: 123 | J6: 6400000 | L6: 41 to 50 | M6: 2350000 | N6: 200 | O6: 3633600 | P6: 350
A7: 4 | B7: 400 | C7: 34 | D7: 85000 | E7: 64 | F7: 1200000 | G7: 94 | H7: 3500000 | I7: 124 | J7: 6500000 | L7: 51 to 60 | M7: 5780000 | N7: 450 | O7: 9413600 | P7: 800
A8: 5 | B8: 500 | C8: 35 | D8: 90000 | E8: 65 | F8: 1250000 | G8: 95 | H8: 3600000 | I8: 125 | J8: 6600000 | L8: 61 to 80 | M8: 29550000 | N8: 700 | O8: 38963600 | P8: 1500
A9: 6 | B9: 600 | C9: 36 | D9: 95000 | E9: 66 | F9: 1300000 | G9: 96 | H9: 3700000 | I9: 126 | J9: 6700000 | L9: 81 to 85 | M9: 11500000 | N9: 800 | O9: 50463600 | P9: 2300
A10: 7 | B10: 700 | C10: 37 | D10: 110000 | E10: 67 | F10: 1350000 | G10: 97 | H10: 3800000 | I10: 127 | J10: 6800000 | L10: 86 to 90 | M10: 14000000 | N10: 800 | O10: 64463600 | P10: 3100
A11: 8 | B11: 800 | C11: 38 | D11: 120000 | E11: 68 | F11: 1400000 | G11: 98 | H11: 3900000 | I11: 128 | J11: 6900000 | L11: 91 to 95 | M11: 16500000 | N11: 800 | O11: 80963600 | P11: 3900
A12: 9 | B12: 1000 | C12: 39 | D12: 130000 | E12: 69 | F12: 1450000 | G12: 99 | H12: 4000000 | I12: 129 | J12: 7000000 | L12: 96 to 100 | M12: 19000000 | N12: 800 | O12: 99963600 | P12: 4700
A13: 10 | B13: 2000 | C13: 40 | D13: 190000 | E13: 70 | F13: 1500000 | G13: 100 | H13: 4100000 | I13: 130 | J13: 7100000 | L13: 101 to 105 | M13: 21500000 | N13: 1200 | O13: 121463600 | P13: 5900
A14: 11 | B14: 3000 | C14: 41 | D14: 200000 | E14: 71 | F14: 1550000 | G14: 101 | H14: 4200000 | I14: 131 | J14: 7200000 | L14: 106 to 110 | M14: 24000000 | N14: 1200 | O14: 145463600 | P14: 7100
A15: 12 | B15: 4000 | C15: 42 | D15: 210000 | E15: 72 | F15: 1600000 | G15: 102 | H15: 4300000 | I15: 132 | J15: 7300000 | L15: 111 to 115 | M15: 26500000 | N15: 1200 | O15: 171963600 | P15: 8300
... A20: 17 | B20: 9000 | C20: 47 | D20: 260000 | E20: 77 | F20: 1850000 | G20: 107 | H20: 4800000 | I20: 137 | J20: 7800000 | L20: 136 to 140 | M20: 39000000 | N20: 1600 | O20: 341963600 | P20: 15900
A21: 18 | B21: 10000 | C21: 48 | D21: 270000 | E21: 78 | F21: 1900000 | G21: 108 | H21: 4900000 | I21: 138 | J21: 7900000
A22: 19 | B22: 12000 | C22: 49 | D22: 280000 | E22: 79 | F22: 2000000 | G22: 109 | H22: 5000000 | I22: 139 | J22: 8000000
A23: 20 | B23: 14000 | C23: 50 | D23: 380000 | E23: 80 | F23: 2100000 | G23: 110 | H23: 5100000 | I23: 140 | J23: MAX
A24: 21 | B24: 16000 | C24: 51 | D24: 400000 | E24: 81 | F24: 2200000 | G24: 111 | H24: 5200000
A25: 22 | B25: 18000 | C25: 52 | D25: 450000 | E25: 82 | F25: 2300000 | G25: 112 | H25: 5300000
A26: 23 | B26: 20000 | C26: 53 | D26: 500000 | E26: 83 | F26: 2400000 | G26: 113 | H26: 5400000
A27: 24 | B27: 25000 | C27: 54 | D27: 550000 | E27: 84 | F27: 2500000 | G27: 114 | H27: 5500000
A28: 25 | B28: 30000 | C28: 55 | D28: 600000 | E28: 85 | F28: 2600000 | G28: 115 | H28: 5600000
A29: 26 | B29: 35000 | C29: 56 | D29: 650000 | E29: 86 | F29: 2700000 | G29: 116 | H29: 5700000
A30: 27 | B30: 40000 | C30: 57 | D30: 700000 | E30: 87 | F30: 2800000 | G30: 117 | H30: 5800000
A31: 28 | B31: 45000 | C31: 58 | D31: 750000 | E31: 88 | F31: 2900000 | G31: 118 | H31: 5900000
A32: 29 | B32: 50000 | C32: 59 | D32: 800000 | E32: 89 | F32: 3000000 | G32: 119 | H32: 6000000

Sheet Blueprints
A1: BLUEPRINTS
B2: Tier 1 | C2: Tier 2 | D2: Tier 3 | E2: Tier 4 | F2: Tier 5 | G2: Tier 6 | H2: Tier 7 | I2: Tier 8 | J2: Tier 9 | K2: Tier 10 | L2: Tier 11 | M2: Tier 12 | N2: Tier 13 | O2: Tier 14 | P2: Tier 15 | Q2: Tier 16 | R2: Tier 17 | S2: Tier 18 | T2: Tier 19 | U2: Tier 20 | V2: Tier 21
B3: 20 | C3: 90 | D3: 180 | E3: 390 | F3: 620 | G3: 1220 | H3: 1870 | I3: 2920 | J3: 4470 | K3: 6520 | L3: 8700 | M3: 9900 | N3: 11000 | O3: 13000 | P3: 15000 | Q3: 17000 | R3: 20000 | S3: 24000 | T3: 29000 | U3: 34000 | V3: 39000
B4: 30 | C4: 90 | D4: 200 | E4: 390 | F4: 670 | G4: 1220 | H4: 1970 | I4: 2920 | J4: 4670 | K4: 6520 | L4: 8700 | M4: 9900 | N4: 11000 | O4: 13000 | P4: 15000 | Q4: 17000 | R4: 20000 | S4: 24000 | T4: 29000 | U4: 34000 | V4: 39000
B5: 30 | C5: 100 | D5: 220 | E5: 410 | F5: 720 | G5: 1270 | H5: 2070 | I5: 3070 | J5: 4870 | K5: 6770 | L5: 8700 | M5: 9900 | N5: 11000 | O5: 13000 | P5: 15000 | Q5: 17000 | R5: 20000 | S5: 24000 | T5: 29000 | U5: 34000 | V5: 39000
B6: 40 | C6: 110 | D6: 240 | E6: 430 | F6: 770 | G6: 1320 | H6: 2170 | I6: 3220 | J6: 5070 | K6: 7020 | L6: 9000 | M6: 10000 | N6: 11600 | O6: 13000 | P6: 15000 | Q6: 18000 | R6: 21300 | S6: 26000 | T6: 30000 | U6: 35000 | V6: 40000
B7: 40 | C7: 110 | D7: 240 | E7: 430 | F7: 770 | G7: 1320 | H7: 2170 | I7: 3220 | J7: 5070 | K7: 7020 | L7: 9000 | M7: 10000 | N7: 11600 | O7: 13000 | P7: 15000 | Q7: 18000 | R7: 21300 | S7: 26000 | T7: 30000 | U7: 35000 | V7: 40000
B8: 50 | C8: 120 | D8: 260 | E8: 450 | F8: 820 | G8: 1370 | H8: 2270 | I8: 3370 | J8: 5270 | K8: 7270 | L8: 9000 | M8: 10000 | N8: 11600 | O8: 13000 | P8: 15000 | Q8: 18000 | R8: 21300 | S8: 26000 | T8: 30000 | U8: 35000 | V8: 40000
B9: 50 | C9: 120 | D9: 280 | E9: 470 | F9: 870 | G9: 1420 | H9: 2370 | I9: 3520 | J9: 5470 | K9: 7520 | L9: 9300 | M9: 11000 | N9: 12000 | O9: 14000 | P9: 16000 | Q9: 19000 | R9: 22000 | S9: 27000 | T9: 32000 | U9: 36000 | V9: 41000
B10: 60 | C10: 130 | D10: 300 | E10: 490 | F10: 920 | G10: 1470 | H10: 2470 | I10: 3670 | J10: 5670 | K10: 7520 | L10: 9300 | M10: 11000 | N10: 12000 | O10: 14000 | P10: 16000 | Q10: 19000 | R10: 22000 | S10: 27000 | T10: 32000 | U10: 36000 | V10: 41000
B11: 80 | C11: 140 | D11: 300 | E11: 490 | F11: 920 | G11: 1470 | H11: 2470 | I11: 3670 | J11: 5670 | K11: 7770 | L11: 9300 | M11: 11000 | N11: 12000 | O11: 14000 | P11: 16000 | Q11: 19000 | R11: 22000 | S11: 27000 | T11: 32000 | U11: 36000 | V11: 41000
C12: 170 | D12: 320 | E12: 510 | F12: 970 | G12: 1520 | H12: 2570 | I12: 3820 | J12: 5870 | K12: 8020 | L12: 9600 | M12: 11000 | N12: 12000 | O12: 14000 | P12: 17000 | Q12: 20000 | R12: 23000 | S12: 28000 | T12: 33000 | U12: 38000 | V12: 42000
D13: 340 | E13: 530 | F13: 1020 | G13: 1570 | H13: 2670 | I13: 3970 | J13: 6070 | K13: 8470 | L13: 9600 | M13: 11000 | N13: 12000 | O13: 14000 | P13: 17000 | Q13: 20000 | R13: 23000 | S13: 28000 | T13: 33000 | U13: 38000 | V13: 42000
D14: 360 | E14: 530 | F14: 1070 | G14: 1570 | H14: 2770 | I14: 3970 | J14: 6270 | L14: 9600 | M14: 11000 | N14: 12000 | O14: 14000 | P14: 17000 | Q14: 20000 | R14: 23000 | S14: 28000 | T14: 33000 | U14: 38000 | V14: 42000
D15: 370 | E15: 550 | F15: 1170 | G15: 1620 | I15: 4120
E16: 570 | G16: 1670 | I16: 4270
E17: 570 | G17: 1770
A18: Total | B18: =SUM(B3:B17) -> 400 | C18: =SUM(C3:C17) -> 1180 | D18: =SUM(D3:D17) -> 3610 | E18: =SUM(E3:E17) -> 7210 | F18: =SUM(F3:F17) -> 11310 | G18: =SUM(G3:G17) -> 21800 | H18: =SUM(H3:H17) -> 27840 | I18: =SUM(I3:I17) -> 49730 | ... V18: =SUM(V3:V17) -> 486000
A20: MASTER BLUEPRINTS - GROUP BATTLE
B21: Hit Song | C21: Artist Training | D21: Gold Bar | E21: Adv Supply | F21: Concert Promo | G21: Stadium Live | H21: Group Strat | I21: Talent Scout | J21: Ace Prod. | K21: Fan Oper. | L21: Elimin. | M21: Prime Supply
A22: 0 | B22: 50 | C22: 50 | D22: 50 | E22: 100 | F22: 100 | G22: 100 | H22: 200 | I22: 200 | J22: 200 | K22: 200 | L22: 200 | M22: 500
A23: 1 | B23: 50 | C23: 50 | D23: 50
A24: 2
A25: 3
A26: 4
A27: 5
A28: 6
A29: 7
A30: 8 | B30: 200 | C30: 200 | D30: 200
A31: 9 | B31: 350 | C31: 350 | D31: 350
A32: Total | B32: =SUM(B22:B31) -> 650 | C32: =SUM(C22:C31) -> 650 | D32: =SUM(D22:D31) -> 650 | E32: =SUM(E22:E31) -> 100 | F32: =SUM(F22:F31) -> 100 | G32: =SUM(G22:G31) -> 100 | H32: =SUM(H22:H31) -> 200 | I32: =SUM(I22:I31) -> 200 | ... M32: =SUM(M22:M31) -> 500
A34: MASTER BLUEPRINTS - EXPANSION
B35: Mkt Master | C35: Hiphop Sing | D35: Hiphop Dance | E35: R&B Sing | F35: R&B Dance | G35: Rock Sing | H35: Rock Dance | I35: EDM Sing | J35: EDM Dance | K35: Pop Sing | L35: Pop Dance | M35: Fan Cap | N35: Quiet Toil | O35: Highl. Momen | P35: Mkt Master | Q35: Rally Cap
A36: 0 | B36: 100 | C36: 200 | D36: 200 | E36: 200 | F36: 200 | G36: 200 | H36: 200 | I36: 200 | J36: 200 | K36: 200 | L36: 200 | M36: 1500 | N36: 2000 | O36: 2000 | P36: 2000 | Q36: 2000
A37: 1 | B37: 200 | C37: 400 | D37: 400 | E37: 400 | F37: 400 | G37: 400 | H37: 400 | I37: 400 | J37: 400 | K37: 400 | L37: 400
A38: 2 | C38: 600 | D38: 600 | E38: 600 | F38: 600 | G38: 600 | H38: 600 | I38: 600 | J38: 600 | K38: 600 | L38: 600
A39: 3
A40: 4
A41: 5 | B41: 500
A42: 6
...

Sheet Others
A1: HQ Building Cards | E1: Business Building Gold
A2: Level | B2: Cards | C2: Accum. | E2: Level | F2: Gold | G2: Gold Accum.
A3: 1 | B3: 2 | C3: 2 | E3: 1 | F3: 100 | G3: 100
A4: 2 | B4: 20 | C4: 22 | E4: 2 | F4: 10000 | G4: 10100
A5: 3 | B5: 100 | C5: 122 | E5: 3 | F5: 50000 | G5: 60100
A6: 4 | B6: 200 | C6: 322 | E6: 4 | F6: 100000 | G6: 160100
A7: 5 | B7: 400 | C7: 722 | E7: 5 | F7: 200000 | G7: 360100
A8: 6 | B8: 800 | C8: 1522 | E8: 6 | F8: 400000 | G8: 760100
A9: 7 | B9: 1400 | C9: 2922 | E9: 7 | F9: 700000 | G9: 1460100
A10: 8 | B10: 2000 | C10: 4922 | E10: 8 | F10: 1000000 | G10: 2460100
A11: 9 | B11: 2600 | C11: 7522 | E11: 9 | F11: 1300000 | G11: 3760100
A12: 10 | B12: 3200 | C12: 10722 | E12: 10 | F12: 1600000 | G12: 5360100
A13: 11 | B13: 3600 | C13: 14322 | E13: 11 | F13: 1800000 | G13: 7160100
A14: 12 | B14: 4000 | C14: 18322 | E14: 12 | F14: 2000000 | G14: 9160100
... A16: 14 | B16: 6000 | C16: 29922 | E16: 14 | F16: 3000000 | G16: 14860100
A17: 15 | B17: MAX | E17: 15 | F17: MAX

Sheet Tables
A1: HQ GLASS | D1: GEMS | G1: CAR PARTS | L1: VILLA | T1: Floor 1 | V1: F2 | X1: F3 | Z1: F4 | AB1: F5 | AD1: Room 1 | AF1: R2 | AH1: R3 | AJ1: R4 | AL1: R5 | AN1: D Grade | AP1: C | AR1: B | AT1: A | AV1: A+ | AX1: Tier 1 | AZ1: T2 | BB1: T3 | BD1: T4 | BF1: T5 | BI1: Floor 1 | BK1: F2 | BM1: F3 | BO1: F4 | BQ1: F5 | BT1: Room 1 | BV1: R2 | BX1: R3 | BZ1: R4 | CB1: R5 | CE1: D Grade | CG1: C | CI1: B | CK1: A | CM1: A+ | CP1: Tier 1 | CR1: T2 | CT1: T3 | CV1: T4 | CX1: T5 | CZ1: ARTIST | DE1: ASSETS | DS1: Assets Acum
A2: Level | B2: Glass | C2: Glass Ac | D2: Level | E2: Gems | F2: Gems Ac | G2: Rank | H2: All 04 Parts | I2: Parts Ac | J2: Drawings | K2: Draw Acum | L2: Villa | M2: Droids | N2: D Acum | O2: Drafts | P2: Drafts Ac | Q2: RANKS | R2: TIERS | S2: Level | T2: Wood | U2: Steel | V2: Wood | W2: Steel | X2: Wood | Y2: Steel | Z2: HQ Wood | AA2: HQ Steel | AB2: HQ Wood | AC2: HQ Steel | AD2: Sandstone | AE2: Tile | AF2: Sandstone | AG2: Tile | AH2: Sandstone | AI2: Tile | AJ2: HQ Sandstone | AK2: HQ Tile | AL2: HQ Sandstone | AM2: HQ Tile | AN2: Plug | AO2: Coil | AP2: Plug | AQ2: Coil | AR2: Plug | AS2: Coil | AT2: Enhanced Plug | AU2: Enhanced Coil | AV2: Enhanced Plug | AW2: Enhanced Coil | AX2: Coins | AY2: Keys | AZ2: Coins | BA2: Keys | BB2: Coins | BC2: Keys | BD2: HQ Coins | BE2: HQ Keys | BF2: HQ Coins | BG2: HQ Keys | BH2: Level | BI2: Wood | BJ2: Steel | BK2: Wood | BL2: Steel | BM2: Wood | BN2: Steel | BO2: HQ Wood | BP2: HQ Steel | BQ2: HQ Wood | BR2: HQ Steel | BS2: Level | BT2: Sandstone | BU2: Tile | BV2: Sandstone | BW2: Tile | BX2: Sandstone | BY2: Tile | BZ2: HQ Sandstone | CA2: HQ Tile | CB2: HQ Sandstone | CC2: HQ Tile | CD2: Level | CE2: Plug | CF2: Coil | CG2: Plug | CH2: Coil | CI2: Plug | CJ2: Coil | CK2: Enhanced Plug | CL2: Enhanced Coil | CM2: Enhanced Plug | CN2: Enhanced Coil | CO2: Level | CP2: Coins | CQ2: Keys | CR2: Coins | CS2: Keys | CT2: Coins | CU2: Keys | CV2: HQ Coins | CW2: HQ Keys | CX2: HQ Coins | CY2: HQ Keys | CZ2: LEVEL | DA2: EXP CARD | DB2: EXP ACUM | DC2: PROM CARDS | DD2: PROM ACUM | DE2: Type | DF2: Source | DG2: Num | DH2: Level | DI2: Jewelry | DJ2: Car | DK2: Property | DL2: Level | DM2: Jewelry | DN2: Car | DO2: Property | DP2: Level | DQ2: Car | DR2: Property | DS2: Level | DT2: Jewelry | DU2: Car | DV2: Property | DW2: Jewelry | DX2: Car | DY2: Property | DZ2: Jewelry | EA2: Car | EB2: Property | EC2: Level | ED2: Sacrif | EE2: Sacrif Ac
